Workbook

Sheet README
A1: Defence aircraft LCA framework workbook
A3: Purpose | B3: Transparent Excel front-end for a cradle-to-grave defence-aircraft LCA aligned to the dissertation framework: manufacturing, operations, and end-of-life only.
A4: Workflow | B4: 1) Edit blue cells in Aircraft Input, Assemblies, Materials, Fuel Scenarios and Calc EOL. 2) Replace example factor values in OpenLCA Factors with exported openLCA + ecoinvent ReCiPe Midpoint (H) factors. 3) Review Checks. 4) Read Results and Sensitivity.
A5: Boundary | B5: Manufacturing + operations + end-of-life. Maintenance, munitions/payloads and infrastructure excluded to remain directly aligned with the dissertation boundary.
A6: Functional unit | B6: One aircraft over the stated lifetime flight hours.
A7: Method | B7: ReCiPe Midpoint (H) factor structure with openLCA-exported lookups. GWP is the primary headline output; additional midpoint columns are included for modular expansion.
A8: Data quality | B8: Every input should be tagged as Measured / Estimated / Proxy / Assumed. Default uncertainty bands are stored in Data Quality.
A9: Notes | B9: Cells in blue are user-editable inputs. Green cells are linked/imported lookup values. Gray cells are static labels. Orange or red highlights indicate caution or failed checks.
A11: Workbook sheets
A12: Aircraft Input | B12: Aircraft metadata, boundary controls and fuel-burn parameters
A13: Assemblies | B13: Assembly masses, logistics and data-class inputs
A14: Materials | B14: Material composition by assembly
A15: Fuel Scenarios | B15: Fuel properties, scenario blends and fuel-factor helper table
A16: Data Quality | B16: Default uncertainty values by data class
A17: OpenLCA Factors | B17: Lookup table to replace with exported openLCA/ecoinvent factors
A18: Calc Materials | B18: Derived material masses and raw-material impacts
A19: Calc Manufacturing | B19: Manufacturing energy, transport and manufacturing totals
A20: Calc Operations | B20: Fuel burn, WTT/TTW impacts and fuel ranges
A21: Calc EOL | B21: Material routing and end-of-life impacts
A22: Sensitivity | B22: Low/base/high totals and scenario comparisons
A23: Results | B23: Headline per-aircraft and fleet outputs
... A25: Fleet Register | B25: Simple fleet aggregation register

Sheet Aircraft Input
A1: Aircraft input and control sheet
A3: Core aircraft definition | E3: Derived / control checks
A4: Aircraft_Name | B4: Eurofighter Typhoon | C4: Worked example | E4: Manufacturing boundary | F4: Manufacturing includes raw material supply, processing energy and inbound transport.
A5: Variant | B5: Tranche / generic open-source model | C5: User-editable | E5: Operations boundary | F5: Operational phase includes WTT + TTW fuel impacts only.
A6: Aircraft_Class | B6: Frontline combat aircraft | C6: User-editable | E6: End-of-life boundary | F6: Material routing + dismantling energy only.
A7: Empty_Mass_kg | B7: 11000 | C7: Typhoon example | E7: Scenario logic | F7: Low/high operations use low/high AlphaDry and fAB values.
A8: MTOW_kg | B8: 23500 | C8: Example | E8: Coverage expectation | F8: Blue cells may be replaced by platform-specific values without changing formulas.
A9: Service_Life_hr | B9: 6000 | C9: Set based on configuration
A10: Fleet_Size | B10: 1 | C10: Set >1 for fleet results
A11: Annual_Fleet_Hours | B11: 250 | C11: Illustrative
A12: Num_Engines | B12: 2 | C12: Set based on configuration
A13: Fdry_Max_kN | B13: 60 | C13: Per engine
A14: FAB_Max_kN | B14: 90 | C14: Per engine
A15: TSFC_dry_g_kNs | B15: 22 | C15: Per engine
A16: TSFC_AB_g_kNs | B16: 48 | C16: Per engine
A17: AlphaDry_Low | B17: 0.15 | C17: Sensitivity lower bound
A18: AlphaDry_Base | B18: 0.3 | C18: Baseline
A19: AlphaDry_High | B19: 0.5 | C19: Sensitivity upper bound
A20: AlphaAB_Base | B20: 0.5 | C20: Baseline
... A24: Fuel_Capacity_kg | B24: 7600 | C24: Typhoon example
A25: Final_Assembly_Location | B25: Warton, Lancashire, UK | C25: Receiving location
A26: Proxy_Aircraft | B26: Airbus A320 family | C26: For proxy scaling
A27: Baseline_Scenario | B27: JetA1_100 | C27: Must match Calc Operations scenario
A28: LCIA_Method | B28: ReCiPe Midpoint (H) | C28: Framework default
A29: Database_Version | B29: ecoinvent + openLCA export | C29: Replace with your version

Sheet Assemblies
A1: Assembly inventory
A5: Assembly ID | B5: Assembly Name | C5: Include YN | D5: Mass Input kg | E5: MassShare Empty | F5: Used Mass kg | G5: Assembly Class | H5: Reuse Eligible YN | I5: Origin Region | J5: Road km Origin | K5: Sea km | L5: Road km Final | M5: Data Class | N5: Source
A6: FUS | B6: Fuselage | C6: Y | D6: 2871 | E6: 0.261 | F6: =IF(C6="N",0,IF(D6<>"",D6,E6*'Aircraft Input'!$B$7)) -> 2871 | G6: Airframe | H6: N | I6: UK | J6: 50 | K6: 0 | L6: 50 | M6: Estimated | N6: Typhoon + A320 proxy scaling
A7: WNG | B7: Wings | C7: Y | D7: 3970 | E7: 0.36090909 | F7: =IF(C7="N",0,IF(D7<>"",D7,E7*'Aircraft Input'!$B$7)) -> 3970 | G7: Airframe | H7: N | I7: Spain/Italy | J7: 150 | K7: 1000 | L7: 100 | M7: Estimated | N7: Typhoon wing inventory
A8: EMP | B8: Empennage | C8: Y | D8: 660 | E8: 0.06 | F8: =IF(C8="N",0,IF(D8<>"",D8,E8*'Aircraft Input'!$B$7)) -> 660 | G8: Airframe | H8: N | I8: Spain/Italy/UK | J8: 100 | K8: 600 | L8: 80 | M8: Proxy | N8: A320 stabiliser template + Typhoon logic
A9: PRO | B9: Propulsion | C9: Y | D9: 2000 | E9: 0.18181818 | F9: =IF(C9="N",0,IF(D9<>"",D9,E9*'Aircraft Input'!$B$7)) -> 2000 | G9: Propulsion | H9: Y | I9: UK/Italy/Germany/Spain | J9: 180 | K9: 800 | L9: 100 | M9: Estimated | N9: EJ200 open-source reconstruction
A10: LGR | B10: Landing Gear | C10: Y | D10: 1242 | E10: 0.11290909 | F10: =IF(C10="N",0,IF(D10<>"",D10,E10*'Aircraft Input'!$B$7)) -> 1242 | G10: LandingGear | H10: N | I10: UK/France/Germany/Italy | J10: 200 | K10: 700 | L10: 100 | M10: Proxy | N10: A320 landing-gear proxy + Typhoon routing
A11: SYS | B11: Systems Other | C11: Y | D11: 257 | E11: 0.023363636 | F11: =IF(C11="N",0,IF(D11<>"",D11,E11*'Aircraft Input'!$B$7)) -> 257 | G11: Systems | H11: N | I11: Mixed | J11: 100 | K11: 200 | L11: 50 | M11: Assumed | N11: Residual mass closure
A13: TOTAL | E13: =SUM(E6:E11) -> 1 | F13: =SUM(F6:F11) -> 11000

Sheet Materials
A1: Material composition by assembly
A5: Assembly ID | B5: Material | C5: Material Group | D5: Percent Input | E5: Normalised Percent | F5: Data Class | G5: Source | H5: Override YN | J5: Assembly | K5: Input % Sum | L5: Normalised % Sum
A6: FUS | B6: CFRP | C6: Composite | D6: 0.81678858 | E6: =IF(SUMIF($A$6:$A$53,$A6,$D$6:$D$53)=0,0,$D6/SUMIF($A$6:$A$53,$A6,$D$6:$D$53)) -> 0.81678858 | F6: Estimated | G6: Typhoon fuselage inventory / scaled metals split | H6: N | J6: FUS | K6: =SUMIF($A$6:$A$53,J6,$D$6:$D$53) -> 1 | L6: =SUMIF($A$6:$A$53,J6,$E$6:$E$53) -> 1
A7: FUS | B7: GFRP | C7: Composite | D7: 0.11424591 | E7: =IF(SUMIF($A$6:$A$53,$A7,$D$6:$D$53)=0,0,$D7/SUMIF($A$6:$A$53,$A7,$D$6:$D$53)) -> 0.11424591 | F7: Estimated | G7: Typhoon fuselage inventory / scaled metals split | H7: N | J7: WNG | K7: =SUMIF($A$6:$A$53,J7,$D$6:$D$53) -> 1 | L7: =SUMIF($A$6:$A$53,J7,$E$6:$E$53) -> 1
A8: FUS | B8: Titanium | C8: Metal | D8: 0.028039011 | E8: =IF(SUMIF($A$6:$A$53,$A8,$D$6:$D$53)=0,0,$D8/SUMIF($A$6:$A$53,$A8,$D$6:$D$53)) -> 0.028039011 | F8: Estimated | G8: Typhoon fuselage inventory / scaled metals split | H8: N | J8: EMP | K8: =SUMIF($A$6:$A$53,J8,$D$6:$D$53) -> 1 | L8: =SUMIF($A$6:$A$53,J8,$E$6:$E$53) -> 1
A9: FUS | B9: NickelSuperalloy | C9: Metal | D9: 0 | E9: =IF(SUMIF($A$6:$A$53,$A9,$D$6:$D$53)=0,0,$D9/SUMIF($A$6:$A$53,$A9,$D$6:$D$53)) -> 0 | F9: Estimated | G9: Typhoon fuselage inventory / scaled metals split | H9: N | J9: PRO | K9: =SUMIF($A$6:$A$53,J9,$D$6:$D$53) -> 1 | L9: =SUMIF($A$6:$A$53,J9,$E$6:$E$53) -> 1
A10: FUS | B10: Steel | C10: Metal | D10: 0 | E10: =IF(SUMIF($A$6:$A$53,$A10,$D$6:$D$53)=0,0,$D10/SUMIF($A$6:$A$53,$A10,$D$6:$D$53)) -> 0 | F10: Estimated | G10: Typhoon fuselage inventory / scaled metals split | H10: N | J10: LGR | K10: =SUMIF($A$6:$A$53,J10,$D$6:$D$53) -> 1 | L10: =SUMIF($A$6:$A$53,J10,$E$6:$E$53) -> 1
A11: FUS | B11: Aluminium | C11: Metal | D11: 0.028039011 | E11: =IF(SUMIF($A$6:$A$53,$A11,$D$6:$D$53)=0,0,$D11/SUMIF($A$6:$A$53,$A11,$D$6:$D$53)) -> 0.028039011 | F11: Estimated | G11: Typhoon fuselage inventory / scaled metals split | H11: N | J11: SYS | K11: =SUMIF($A$6:$A$53,J11,$D$6:$D$53) -> 1 | L11: =SUMIF($A$6:$A$53,J11,$E$6:$E$53) -> 1
A12: FUS | B12: Electronics | C12: Electronics | D12: 0 | E12: =IF(SUMIF($A$6:$A$53,$A12,$D$6:$D$53)=0,0,$D12/SUMIF($A$6:$A$53,$A12,$D$6:$D$53)) -> 0 | F12: Estimated | G12: Typhoon fuselage inventory / scaled metals split | H12: N
A13: FUS | B13: Other | C13: Other | D13: 0.012887496 | E13: =IF(SUMIF($A$6:$A$53,$A13,$D$6:$D$53)=0,0,$D13/SUMIF($A$6:$A$53,$A13,$D$6:$D$53)) -> 0.012887496 | F13: Estimated | G13: Typhoon fuselage inventory / scaled metals split | H13: N
A14: WNG | B14: CFRP | C14: Composite | D14: 0.72972292 | E14: =IF(SUMIF($A$6:$A$53,$A14,$D$6:$D$53)=0,0,$D14/SUMIF($A$6:$A$53,$A14,$D$6:$D$53)) -> 0.72972292 | F14: Estimated | G14: Typhoon wing inventory | H14: N
A15: WNG | B15: GFRP | C15: Composite | D15: 0.11083123 | E15: =IF(SUMIF($A$6:$A$53,$A15,$D$6:$D$53)=0,0,$D15/SUMIF($A$6:$A$53,$A15,$D$6:$D$53)) -> 0.11083123 | F15: Estimated | G15: Typhoon wing inventory | H15: N
A16: WNG | B16: Titanium | C16: Metal | D16: 0.12166247 | E16: =IF(SUMIF($A$6:$A$53,$A16,$D$6:$D$53)=0,0,$D16/SUMIF($A$6:$A$53,$A16,$D$6:$D$53)) -> 0.12166247 | F16: Estimated | G16: Typhoon wing inventory | H16: N
A17: WNG | B17: NickelSuperalloy | C17: Metal | D17: 0 | E17: =IF(SUMIF($A$6:$A$53,$A17,$D$6:$D$53)=0,0,$D17/SUMIF($A$6:$A$53,$A17,$D$6:$D$53)) -> 0 | F17: Estimated | G17: Typhoon wing inventory | H17: N
A18: WNG | B18: Steel | C18: Metal | D18: 0 | E18: =IF(SUMIF($A$6:$A$53,$A18,$D$6:$D$53)=0,0,$D18/SUMIF($A$6:$A$53,$A18,$D$6:$D$53)) -> 0 | F18: Estimated | G18: Typhoon wing inventory | H18: N
A19: WNG | B19: Aluminium | C19: Metal | D19: 0.016372796 | E19: =IF(SUMIF($A$6:$A$53,$A19,$D$6:$D$53)=0,0,$D19/SUMIF($A$6:$A$53,$A19,$D$6:$D$53)) -> 0.016372796 | F19: Estimated | G19: Typhoon wing inventory | H19: N
A20: WNG | B20: Electronics | C20: Electronics | D20: 0 | E20: =IF(SUMIF($A$6:$A$53,$A20,$D$6:$D$53)=0,0,$D20/SUMIF($A$6:$A$53,$A20,$D$6:$D$53)) -> 0 | F20: Estimated | G20: Typhoon wing inventory | H20: N
A21: WNG | B21: Other | C21: Other | D21: 0.021410579 | E21: =IF(SUMIF($A$6:$A$53,$A21,$D$6:$D$53)=0,0,$D21/SUMIF($A$6:$A$53,$A21,$D$6:$D$53)) -> 0.021410579 | F21: Estimated | G21: Typhoon wing inventory | H21: N
A22: EMP | B22: CFRP | C22: Composite | D22: 0.88787879 | E22: =IF(SUMIF($A$6:$A$53,$A22,$D$6:$D$53)=0,0,$D22/SUMIF($A$6:$A$53,$A22,$D$6:$D$53)) -> 0.88787879 | F22: Proxy | G22: Typhoon stabiliser proxy aggregation | H22: N
A23: EMP | B23: GFRP | C23: Composite | D23: 0.10151515 | E23: =IF(SUMIF($A$6:$A$53,$A23,$D$6:$D$53)=0,0,$D23/SUMIF($A$6:$A$53,$A23,$D$6:$D$53)) -> 0.10151515 | F23: Proxy | G23: Typhoon stabiliser proxy aggregation | H23: N
... A53: SYS | B53: Other | C53: Other | D53: 0.1 | E53: =IF(SUMIF($A$6:$A$53,$A53,$D$6:$D$53)=0,0,$D53/SUMIF($A$6:$A$53,$A53,$D$6:$D$53)) -> 0.1 | F53: Assumed | G53: Residual mass closure assumption | H53: N

Sheet Fuel Scenarios
A1: Fuel properties and scenario blends
A4: Fuel property table
A5: Fuel Type | B5: Density kg per L | C5: WTT Key | D5: TTW Key | E5: WTT GWP100 | F5: WTT FDP | G5: WTT PMFP | H5: WTT_TAP100 | I5: WTT FEP | J5: WTT HTPinf | K5: WTT IRP HE | L5: WTT METPinf | M5: TTW GWP100 | N5: TTW FDP | O5: TTW PMFP | P5: TTW TAP100 | Q5: TTW FEP | R5: TTW HTPinf | S5: TTW IRP HE | T5: TTW METPinf | U5: Notes | X5: Scenario Name | Y5: Fuel Type | Z5: Volume Share | AA5: Density kg per L | AB5: WTT GWP100 | AC5: WTT FDP | AD5: WTT PMFP | AE5: WTT TAP100 | AF5: WTT FEP | AG5: WTT HTPinf | AH5: WTT IRP HE | AI5: WTT METPinf | AJ5: TTW GWP100 | AK5: TTW FDP | AL5: TTW PMFP | AM5: TTW TAP100 | AN5: TTW FEP | AO5: TTW HTPinf | AP5: TTW IRP HE | AQ5: TTW METPinf | AR5: Mass per L Contribution | AS5: GWP100 Contribution | AT5: FDP Contribution | AU5: PMFP Contribution | AV5: TAP100 Contribution | AW5: FEP Contribution | AX5: HTPinf Contribution | AY5: IRP HE Contribution | AZ5: METPinf Contribution | BC5: Scenario Name | BD5: Mass per L | BE5: GWP100 | BF5: FDP | BG5: PMFP | BH5: TAP100 | BI5: FEP | BJ5: HTPinf | BK5: IRP HE | BL5: METPinf
A6: Jet-A1 | B6: 0.8 | C6: Fuel_WTT_Jet-A1 | D6: Fuel_TTW_Jet-A1 | E6: =IFERROR(VLOOKUP($C6,'OpenLCA Factors'!$A$6:$L$200,4,FALSE),0) -> 0.59 | F6: =IFERROR(VLOOKUP($C6,'OpenLCA Factors'!$A$6:$L$200,5,FALSE),0) -> 0.45 | G6: =IFERROR(VLOOKUP($C6,'OpenLCA Factors'!$A$6:$L$200,6,FALSE),0) -> 0.0012 | H6: =IFERROR(VLOOKUP($C6,'OpenLCA Factors'!$A$6:$L$200,7,FALSE),0) -> 0.002 | I6: =IFERROR(VLOOKUP($C6,'OpenLCA Factors'!$A$6:$L$200,8,FALSE),0) -> 5e-05 | J6: =IFERROR(VLOOKUP($C6,'OpenLCA Factors'!$A$6:$L$200,9,FALSE),0) -> 0.3 | K6: =IFERROR(VLOOKUP($C6,'OpenLCA Factors'!$A$6:$L$200,10,FALSE),0) -> 0.002 | L6: =IFERROR(VLOOKUP($C6,'OpenLCA Factors'!$A$6:$L$200,11,FALSE),0) -> 0.1 | M6: =IFERROR(VLOOKUP($D6,'OpenLCA Factors'!$A$6:$L$200,4,FALSE),0) -> 3.15 | N6: =IFERROR(VLOOKUP($D6,'OpenLCA Factors'!$A$6:$L$200,5,FALSE),0) -> 1 | O6: =IFERROR(VLOOKUP($D6,'OpenLCA Factors'!$A$6:$L$200,6,FALSE),0) -> 0.0025 | P6: =IFERROR(VLOOKUP($D6,'OpenLCA Factors'!$A$6:$L$200,7,FALSE),0) -> 0.0035 | Q6: =IFERROR(VLOOKUP($D6,'OpenLCA Factors'!$A$6:$L$200,8,FALSE),0) -> 8e-05 | R6: =IFERROR(VLOOKUP($D6,'OpenLCA Factors'!$A$6:$L$200,9,FALSE),0) -> 0.5 | S6: =IFERROR(VLOOKUP($D6,'OpenLCA Factors'!$A$6:$L$200,10,FALSE),0) -> 0.001 | T6: =IFERROR(VLOOKUP($D6,'OpenLCA Factors'!$A$6:$L$200,11,FALSE),0) -> 0.05 | U6: Replace these linked defaults with project-specific openLCA export factors. | X6: JetA1_100 | Y6: Jet-A1 | Z6: 1 | AA6: =IFERROR(VLOOKUP($Y6,$A$6:$U$20,2,FALSE),0) -> 0.8 | AB6: =IFERROR(VLOOKUP($Y6,$A$6:$U$20,5,FALSE),0) -> 0.59 | AC6: =IFERROR(VLOOKUP($Y6,$A$6:$U$20,6,FALSE),0) -> 0.45 | AD6: =IFERROR(VLOOKUP($Y6,$A$6:$U$20,7,FALSE),0) -> 0.0012 | AE6: =IFERROR(VLOOKUP($Y6,$A$6:$U$20,8,FALSE),0) -> 0.002 | AF6: =IFERROR(VLOOKUP($Y6,$A$6:$U$20,9,FALSE),0) -> 5e-05 | AG6: =IFERROR(VLOOKUP($Y6,$A$6:$U$20,10,FALSE),0) -> 0.3 | AH6: =IFERROR(VLOOKUP($Y6,$A$6:$U$20,11,FALSE),0) -> 0.002 | AI6: =IFERROR(VLOOKUP($Y6,$A$6:$U$20,12,FALSE),0) -> 0.1 | AJ6: =IFERROR(VLOOKUP($Y6,$A$6:$U$20,13,FALSE),0) -> 3.15 | AK6: =IFERROR(VLOOKUP($Y6,$A$6:$U$20,14,FALSE),0) -> 1 | AL6: =IFERROR(VLOOKUP($Y6,$A$6:$U$20,15,FALSE),0) -> 0.0025 | AM6: =IFERROR(VLOOKUP($Y6,$A$6:$U$20,16,FALSE),0) -> 0.0035 | AN6: =IFERROR(VLOOKUP($Y6,$A$6:$U$20,17,FALSE),0) -> 8e-05 | AO6: =IFERROR(VLOOKUP($Y6,$A$6:$U$20,18,FALSE),0) -> 0.5 | AP6: =IFERROR(VLOOKUP($Y6,$A$6:$U$20,19,FALSE),0) -> 0.001 | AQ6: =IFERROR(VLOOKUP($Y6,$A$6:$U$20,20,FALSE),0) -> 0.05 | AR6: =Z6*AA6 -> 0.8 | AS6: =Z6*AA6*(AB6+AJ6) -> 2.992 | AT6: =Z6*AA6*(AC6+AK6) -> 1.16 | AU6: =Z6*AA6*(AD6+AL6) -> 0.00296 | AV6: =Z6*AA6*(AE6+AM6) -> 0.0044 | AW6: =Z6*AA6*(AF6+AN6) -> 0.000104 | AX6: =Z6*AA6*(AG6+AO6) -> 0.64 | AY6: =Z6*AA6*(AH6+AP6) -> 0.0024 | AZ6: =Z6*AA6*(AI6+AQ6) -> 0.12 | BC6: JetA1_100 | BD6: =SUMIF($X$6:$X$20,BC6,$AR$6:$AR$20) -> 0.8 | BE6: =SUMIF($X$6:$X$20,BC6,$AS$6:$AS$20) -> 2.992 | BF6: =SUMIF($X$6:$X$20,BC6,$AT$6:$AT$20) -> 1.16 | BG6: =SUMIF($X$6:$X$20,BC6,$AU$6:$AU$20) -> 0.00296 | BH6: =SUMIF($X$6:$X$20,BC6,$AV$6:$AV$20) -> 0.0044 | BI6: =SUMIF($X$6:$X$20,BC6,$AW$6:$AW$20) -> 0.000104 | BJ6: =SUMIF($X$6:$X$20,BC6,$AX$6:$AX$20) -> 0.64 | BK6: =SUMIF($X$6:$X$20,BC6,$AY$6:$AY$20) -> 0.0024 | BL6: =SUMIF($X$6:$X$20,BC6,$AZ$6:$AZ$20) -> 0.12
A7: HEFA | B7: 0.78 | C7: Fuel_WTT_HEFA | D7: Fuel_TTW_HEFA | E7: =IFERROR(VLOOKUP($C7,'OpenLCA Factors'!$A$6:$L$200,4,FALSE),0) -> 0.9 | F7: =IFERROR(VLOOKUP($C7,'OpenLCA Factors'!$A$6:$L$200,5,FALSE),0) -> 0.2 | G7: =IFERROR(VLOOKUP($C7,'OpenLCA Factors'!$A$6:$L$200,6,FALSE),0) -> 0.0008 | H7: =IFERROR(VLOOKUP($C7,'OpenLCA Factors'!$A$6:$L$200,7,FALSE),0) -> 0.0015 | I7: =IFERROR(VLOOKUP($C7,'OpenLCA Factors'!$A$6:$L$200,8,FALSE),0) -> 4e-05 | J7: =IFERROR(VLOOKUP($C7,'OpenLCA Factors'!$A$6:$L$200,9,FALSE),0) -> 0.25 | K7: =IFERROR(VLOOKUP($C7,'OpenLCA Factors'!$A$6:$L$200,10,FALSE),0) -> 0.001 | L7: =IFERROR(VLOOKUP($C7,'OpenLCA Factors'!$A$6:$L$200,11,FALSE),0) -> 0.08 | M7: =IFERROR(VLOOKUP($D7,'OpenLCA Factors'!$A$6:$L$200,4,FALSE),0) -> 0 | N7: =IFERROR(VLOOKUP($D7,'OpenLCA Factors'!$A$6:$L$200,5,FALSE),0) -> 0 | O7: =IFERROR(VLOOKUP($D7,'OpenLCA Factors'!$A$6:$L$200,6,FALSE),0) -> 0.0002 | P7: =IFERROR(VLOOKUP($D7,'OpenLCA Factors'!$A$6:$L$200,7,FALSE),0) -> 0.0002 | Q7: =IFERROR(VLOOKUP($D7,'OpenLCA Factors'!$A$6:$L$200,8,FALSE),0) -> 1e-05 | R7: =IFERROR(VLOOKUP($D7,'OpenLCA Factors'!$A$6:$L$200,9,FALSE),0) -> 0.02 | S7: =IFERROR(VLOOKUP($D7,'OpenLCA Factors'!$A$6:$L$200,10,FALSE),0) -> 0.0001 | T7: =IFERROR(VLOOKUP($D7,'OpenLCA Factors'!$A$6:$L$200,11,FALSE),0) -> 0.01 | U7: Replace these linked defaults with project-specific openLCA export factors. | X7: HEFA_40 | Y7: Jet-A1 | Z7: 0.6 | AA7: =IFERROR(VLOOKUP($Y7,$A$6:$U$20,2,FALSE),0) -> 0.8 | AB7: =IFERROR(VLOOKUP($Y7,$A$6:$U$20,5,FALSE),0) -> 0.59 | AC7: =IFERROR(VLOOKUP($Y7,$A$6:$U$20,6,FALSE),0) -> 0.45 | AD7: =IFERROR(VLOOKUP($Y7,$A$6:$U$20,7,FALSE),0) -> 0.0012 | AE7: =IFERROR(VLOOKUP($Y7,$A$6:$U$20,8,FALSE),0) -> 0.002 | AF7: =IFERROR(VLOOKUP($Y7,$A$6:$U$20,9,FALSE),0) -> 5e-05 | AG7: =IFERROR(VLOOKUP($Y7,$A$6:$U$20,10,FALSE),0) -> 0.3 | AH7: =IFERROR(VLOOKUP($Y7,$A$6:$U$20,11,FALSE),0) -> 0.002 | AI7: =IFERROR(VLOOKUP($Y7,$A$6:$U$20,12,FALSE),0) -> 0.1 | AJ7: =IFERROR(VLOOKUP($Y7,$A$6:$U$20,13,FALSE),0) -> 3.15 | AK7: =IFERROR(VLOOKUP($Y7,$A$6:$U$20,14,FALSE),0) -> 1 | AL7: =IFERROR(VLOOKUP($Y7,$A$6:$U$20,15,FALSE),0) -> 0.0025 | AM7: =IFERROR(VLOOKUP($Y7,$A$6:$U$20,16,FALSE),0) -> 0.0035 | AN7: =IFERROR(VLOOKUP($Y7,$A$6:$U$20,17,FALSE),0) -> 8e-05 | AO7: =IFERROR(VLOOKUP($Y7,$A$6:$U$20,18,FALSE),0) -> 0.5 | AP7: =IFERROR(VLOOKUP($Y7,$A$6:$U$20,19,FALSE),0) -> 0.001 | AQ7: =IFERROR(VLOOKUP($Y7,$A$6:$U$20,20,FALSE),0) -> 0.05 | AR7: =Z7*AA7 -> 0.48 | AS7: =Z7*AA7*(AB7+AJ7) -> 1.7952 | AT7: =Z7*AA7*(AC7+AK7) -> 0.696 | AU7: =Z7*AA7*(AD7+AL7) -> 0.001776 | AV7: =Z7*AA7*(AE7+AM7) -> 0.00264 | AW7: =Z7*AA7*(AF7+AN7) -> 6.24e-05 | AX7: =Z7*AA7*(AG7+AO7) -> 0.384 | AY7: =Z7*AA7*(AH7+AP7) -> 0.00144 | AZ7: =Z7*AA7*(AI7+AQ7) -> 0.072 | BC7: HEFA_40 | BD7: =SUMIF($X$6:$X$20,BC7,$AR$6:$AR$20) -> 0.792 | BE7: =SUMIF($X$6:$X$20,BC7,$AS$6:$AS$20) -> 2.076 | BF7: =SUMIF($X$6:$X$20,BC7,$AT$6:$AT$20) -> 0.7584 | BG7: =SUMIF($X$6:$X$20,BC7,$AU$6:$AU$20) -> 0.002088 | BH7: =SUMIF($X$6:$X$20,BC7,$AV$6:$AV$20) -> 0.0031704 | BI7: =SUMIF($X$6:$X$20,BC7,$AW$6:$AW$20) -> 7.8e-05 | BJ7: =SUMIF($X$6:$X$20,BC7,$AX$6:$AX$20) -> 0.46824 | BK7: =SUMIF($X$6:$X$20,BC7,$AY$6:$AY$20) -> 0.0017832 | BL7: =SUMIF($X$6:$X$20,BC7,$AZ$6:$AZ$20) -> 0.10008
A8: Synthetic_PT_L | B8: 0.79 | C8: Fuel_WTT_SynPTL | D8: Fuel_TTW_SynPTL | E8: =IFERROR(VLOOKUP($C8,'OpenLCA Factors'!$A$6:$L$200,4,FALSE),0) -> 1.3 | F8: =IFERROR(VLOOKUP($C8,'OpenLCA Factors'!$A$6:$L$200,5,FALSE),0) -> 0.35 | G8: =IFERROR(VLOOKUP($C8,'OpenLCA Factors'!$A$6:$L$200,6,FALSE),0) -> 0.001 | H8: =IFERROR(VLOOKUP($C8,'OpenLCA Factors'!$A$6:$L$200,7,FALSE),0) -> 0.0018 | I8: =IFERROR(VLOOKUP($C8,'OpenLCA Factors'!$A$6:$L$200,8,FALSE),0) -> 5e-05 | J8: =IFERROR(VLOOKUP($C8,'OpenLCA Factors'!$A$6:$L$200,9,FALSE),0) -> 0.28 | K8: =IFERROR(VLOOKUP($C8,'OpenLCA Factors'!$A$6:$L$200,10,FALSE),0) -> 0.003 | L8: =IFERROR(VLOOKUP($C8,'OpenLCA Factors'!$A$6:$L$200,11,FALSE),0) -> 0.1 | M8: =IFERROR(VLOOKUP($D8,'OpenLCA Factors'!$A$6:$L$200,4,FALSE),0) -> 0.2 | N8: =IFERROR(VLOOKUP($D8,'OpenLCA Factors'!$A$6:$L$200,5,FALSE),0) -> 0.1 | O8: =IFERROR(VLOOKUP($D8,'OpenLCA Factors'!$A$6:$L$200,6,FALSE),0) -> 0.0005 | P8: =IFERROR(VLOOKUP($D8,'OpenLCA Factors'!$A$6:$L$200,7,FALSE),0) -> 0.0005 | Q8: =IFERROR(VLOOKUP($D8,'OpenLCA Factors'!$A$6:$L$200,8,FALSE),0) -> 2e-05 | R8: =IFERROR(VLOOKUP($D8,'OpenLCA Factors'!$A$6:$L$200,9,FALSE),0) -> 0.05 | S8: =IFERROR(VLOOKUP($D8,'OpenLCA Factors'!$A$6:$L$200,10,FALSE),0) -> 0.0005 | T8: =IFERROR(VLOOKUP($D8,'OpenLCA Factors'!$A$6:$L$200,11,FALSE),0) -> 0.02 | U8: Replace these linked defaults with project-specific openLCA export factors. | X8: HEFA_40 | Y8: HEFA | Z8: 0.4 | AA8: =IFERROR(VLOOKUP($Y8,$A$6:$U$20,2,FALSE),0) -> 0.78 | AB8: =IFERROR(VLOOKUP($Y8,$A$6:$U$20,5,FALSE),0) -> 0.9 | AC8: =IFERROR(VLOOKUP($Y8,$A$6:$U$20,6,FALSE),0) -> 0.2 | AD8: =IFERROR(VLOOKUP($Y8,$A$6:$U$20,7,FALSE),0) -> 0.0008 | AE8: =IFERROR(VLOOKUP($Y8,$A$6:$U$20,8,FALSE),0) -> 0.0015 | AF8: =IFERROR(VLOOKUP($Y8,$A$6:$U$20,9,FALSE),0) -> 4e-05 | AG8: =IFERROR(VLOOKUP($Y8,$A$6:$U$20,10,FALSE),0) -> 0.25 | AH8: =IFERROR(VLOOKUP($Y8,$A$6:$U$20,11,FALSE),0) -> 0.001 | AI8: =IFERROR(VLOOKUP($Y8,$A$6:$U$20,12,FALSE),0) -> 0.08 | AJ8: =IFERROR(VLOOKUP($Y8,$A$6:$U$20,13,FALSE),0) -> 0 | AK8: =IFERROR(VLOOKUP($Y8,$A$6:$U$20,14,FALSE),0) -> 0 | AL8: =IFERROR(VLOOKUP($Y8,$A$6:$U$20,15,FALSE),0) -> 0.0002 | AM8: =IFERROR(VLOOKUP($Y8,$A$6:$U$20,16,FALSE),0) -> 0.0002 | AN8: =IFERROR(VLOOKUP($Y8,$A$6:$U$20,17,FALSE),0) -> 1e-05 | AO8: =IFERROR(VLOOKUP($Y8,$A$6:$U$20,18,FALSE),0) -> 0.02 | AP8: =IFERROR(VLOOKUP($Y8,$A$6:$U$20,19,FALSE),0) -> 0.0001 | AQ8: =IFERROR(VLOOKUP($Y8,$A$6:$U$20,20,FALSE),0) -> 0.01 | AR8: =Z8*AA8 -> 0.312 | AS8: =Z8*AA8*(AB8+AJ8) -> 0.2808 | AT8: =Z8*AA8*(AC8+AK8) -> 0.0624 | AU8: =Z8*AA8*(AD8+AL8) -> 0.000312 | AV8: =Z8*AA8*(AE8+AM8) -> 0.0005304 | AW8: =Z8*AA8*(AF8+AN8) -> 1.56e-05 | AX8: =Z8*AA8*(AG8+AO8) -> 0.08424 | AY8: =Z8*AA8*(AH8+AP8) -> 0.0003432 | AZ8: =Z8*AA8*(AI8+AQ8) -> 0.02808 | BC8: HEFA_100 | BD8: =SUMIF($X$6:$X$20,BC8,$AR$6:$AR$20) -> 0.78 | BE8: =SUMIF($X$6:$X$20,BC8,$AS$6:$AS$20) -> 0.702 | BF8: =SUMIF($X$6:$X$20,BC8,$AT$6:$AT$20) -> 0.156 | BG8: =SUMIF($X$6:$X$20,BC8,$AU$6:$AU$20) -> 0.00078 | BH8: =SUMIF($X$6:$X$20,BC8,$AV$6:$AV$20) -> 0.001326 | BI8: =SUMIF($X$6:$X$20,BC8,$AW$6:$AW$20) -> 3.9e-05 | BJ8: =SUMIF($X$6:$X$20,BC8,$AX$6:$AX$20) -> 0.2106 | BK8: =SUMIF($X$6:$X$20,BC8,$AY$6:$AY$20) -> 0.000858 | BL8: =SUMIF($X$6:$X$20,BC8,$AZ$6:$AZ$20) -> 0.0702
X9: HEFA_100 | Y9: HEFA | Z9: 1 | AA9: =IFERROR(VLOOKUP($Y9,$A$6:$U$20,2,FALSE),0) -> 0.78 | AB9: =IFERROR(VLOOKUP($Y9,$A$6:$U$20,5,FALSE),0) -> 0.9 | AC9: =IFERROR(VLOOKUP($Y9,$A$6:$U$20,6,FALSE),0) -> 0.2 | AD9: =IFERROR(VLOOKUP($Y9,$A$6:$U$20,7,FALSE),0) -> 0.0008 | AE9: =IFERROR(VLOOKUP($Y9,$A$6:$U$20,8,FALSE),0) -> 0.0015 | AF9: =IFERROR(VLOOKUP($Y9,$A$6:$U$20,9,FALSE),0) -> 4e-05 | AG9: =IFERROR(VLOOKUP($Y9,$A$6:$U$20,10,FALSE),0) -> 0.25 | AH9: =IFERROR(VLOOKUP($Y9,$A$6:$U$20,11,FALSE),0) -> 0.001 | AI9: =IFERROR(VLOOKUP($Y9,$A$6:$U$20,12,FALSE),0) -> 0.08 | AJ9: =IFERROR(VLOOKUP($Y9,$A$6:$U$20,13,FALSE),0) -> 0 | AK9: =IFERROR(VLOOKUP($Y9,$A$6:$U$20,14,FALSE),0) -> 0 | AL9: =IFERROR(VLOOKUP($Y9,$A$6:$U$20,15,FALSE),0) -> 0.0002 | AM9: =IFERROR(VLOOKUP($Y9,$A$6:$U$20,16,FALSE),0) -> 0.0002 | AN9: =IFERROR(VLOOKUP($Y9,$A$6:$U$20,17,FALSE),0) -> 1e-05 | AO9: =IFERROR(VLOOKUP($Y9,$A$6:$U$20,18,FALSE),0) -> 0.02 | AP9: =IFERROR(VLOOKUP($Y9,$A$6:$U$20,19,FALSE),0) -> 0.0001 | AQ9: =IFERROR(VLOOKUP($Y9,$A$6:$U$20,20,FALSE),0) -> 0.01 | AR9: =Z9*AA9 -> 0.78 | AS9: =Z9*AA9*(AB9+AJ9) -> 0.702 | AT9: =Z9*AA9*(AC9+AK9) -> 0.156 | AU9: =Z9*AA9*(AD9+AL9) -> 0.00078 | AV9: =Z9*AA9*(AE9+AM9) -> 0.001326 | AW9: =Z9*AA9*(AF9+AN9) -> 3.9e-05 | AX9: =Z9*AA9*(AG9+AO9) -> 0.2106 | AY9: =Z9*AA9*(AH9+AP9) -> 0.000858 | AZ9: =Z9*AA9*(AI9+AQ9) -> 0.0702 | BC9: SynPTL_50 | BD9: =SUMIF($X$6:$X$20,BC9,$AR$6:$AR$20) -> 0.795 | BE9: =SUMIF($X$6:$X$20,BC9,$AS$6:$AS$20) -> 2.0885 | BF9: =SUMIF($X$6:$X$20,BC9,$AT$6:$AT$20) -> 0.75775 | BG9: =SUMIF($X$6:$X$20,BC9,$AU$6:$AU$20) -> 0.0020725 | BH9: =SUMIF($X$6:$X$20,BC9,$AV$6:$AV$20) -> 0.0031085 | BI9: =SUMIF($X$6:$X$20,BC9,$AW$6:$AW$20) -> 7.965e-05 | BJ9: =SUMIF($X$6:$X$20,BC9,$AX$6:$AX$20) -> 0.45035 | BK9: =SUMIF($X$6:$X$20,BC9,$AY$6:$AY$20) -> 0.0025825 | BL9: =SUMIF($X$6:$X$20,BC9,$AZ$6:$AZ$20) -> 0.1074
X10: SynPTL_50 | Y10: Jet-A1 | Z10: 0.5 | AA10: =IFERROR(VLOOKUP($Y10,$A$6:$U$20,2,FALSE),0) -> 0.8 | AB10: =IFERROR(VLOOKUP($Y10,$A$6:$U$20,5,FALSE),0) -> 0.59 | AC10: =IFERROR(VLOOKUP($Y10,$A$6:$U$20,6,FALSE),0) -> 0.45 | AD10: =IFERROR(VLOOKUP($Y10,$A$6:$U$20,7,FALSE),0) -> 0.0012 | AE10: =IFERROR(VLOOKUP($Y10,$A$6:$U$20,8,FALSE),0) -> 0.002 | AF10: =IFERROR(VLOOKUP($Y10,$A$6:$U$20,9,FALSE),0) -> 5e-05 | AG10: =IFERROR(VLOOKUP($Y10,$A$6:$U$20,10,FALSE),0) -> 0.3 | AH10: =IFERROR(VLOOKUP($Y10,$A$6:$U$20,11,FALSE),0) -> 0.002 | AI10: =IFERROR(VLOOKUP($Y10,$A$6:$U$20,12,FALSE),0) -> 0.1 | AJ10: =IFERROR(VLOOKUP($Y10,$A$6:$U$20,13,FALSE),0) -> 3.15 | AK10: =IFERROR(VLOOKUP($Y10,$A$6:$U$20,14,FALSE),0) -> 1 | AL10: =IFERROR(VLOOKUP($Y10,$A$6:$U$20,15,FALSE),0) -> 0.0025 | AM10: =IFERROR(VLOOKUP($Y10,$A$6:$U$20,16,FALSE),0) -> 0.0035 | AN10: =IFERROR(VLOOKUP($Y10,$A$6:$U$20,17,FALSE),0) -> 8e-05 | AO10: =IFERROR(VLOOKUP($Y10,$A$6:$U$20,18,FALSE),0) -> 0.5 | AP10: =IFERROR(VLOOKUP($Y10,$A$6:$U$20,19,FALSE),0) -> 0.001 | AQ10: =IFERROR(VLOOKUP($Y10,$A$6:$U$20,20,FALSE),0) -> 0.05 | AR10: =Z10*AA10 -> 0.4 | AS10: =Z10*AA10*(AB10+AJ10) -> 1.496 | AT10: =Z10*AA10*(AC10+AK10) -> 0.58 | AU10: =Z10*AA10*(AD10+AL10) -> 0.00148 | AV10: =Z10*AA10*(AE10+AM10) -> 0.0022 | AW10: =Z10*AA10*(AF10+AN10) -> 5.2e-05 | AX10: =Z10*AA10*(AG10+AO10) -> 0.32 | AY10: =Z10*AA10*(AH10+AP10) -> 0.0012 | AZ10: =Z10*AA10*(AI10+AQ10) -> 0.06
X11: SynPTL_50 | Y11: Synthetic_PT_L | Z11: 0.5 | AA11: =IFERROR(VLOOKUP($Y11,$A$6:$U$20,2,FALSE),0) -> 0.79 | AB11: =IFERROR(VLOOKUP($Y11,$A$6:$U$20,5,FALSE),0) -> 1.3 | AC11: =IFERROR(VLOOKUP($Y11,$A$6:$U$20,6,FALSE),0) -> 0.35 | AD11: =IFERROR(VLOOKUP($Y11,$A$6:$U$20,7,FALSE),0) -> 0.001 | AE11: =IFERROR(VLOOKUP($Y11,$A$6:$U$20,8,FALSE),0) -> 0.0018 | AF11: =IFERROR(VLOOKUP($Y11,$A$6:$U$20,9,FALSE),0) -> 5e-05 | AG11: =IFERROR(VLOOKUP($Y11,$A$6:$U$20,10,FALSE),0) -> 0.28 | AH11: =IFERROR(VLOOKUP($Y11,$A$6:$U$20,11,FALSE),0) -> 0.003 | AI11: =IFERROR(VLOOKUP($Y11,$A$6:$U$20,12,FALSE),0) -> 0.1 | AJ11: =IFERROR(VLOOKUP($Y11,$A$6:$U$20,13,FALSE),0) -> 0.2 | AK11: =IFERROR(VLOOKUP($Y11,$A$6:$U$20,14,FALSE),0) -> 0.1 | AL11: =IFERROR(VLOOKUP($Y11,$A$6:$U$20,15,FALSE),0) -> 0.0005 | AM11: =IFERROR(VLOOKUP($Y11,$A$6:$U$20,16,FALSE),0) -> 0.0005 | AN11: =IFERROR(VLOOKUP($Y11,$A$6:$U$20,17,FALSE),0) -> 2e-05 | AO11: =IFERROR(VLOOKUP($Y11,$A$6:$U$20,18,FALSE),0) -> 0.05 | AP11: =IFERROR(VLOOKUP($Y11,$A$6:$U$20,19,FALSE),0) -> 0.0005 | AQ11: =IFERROR(VLOOKUP($Y11,$A$6:$U$20,20,FALSE),0) -> 0.02 | AR11: =Z11*AA11 -> 0.395 | AS11: =Z11*AA11*(AB11+AJ11) -> 0.5925 | AT11: =Z11*AA11*(AC11+AK11) -> 0.17775 | AU11: =Z11*AA11*(AD11+AL11) -> 0.0005925 | AV11: =Z11*AA11*(AE11+AM11) -> 0.0009085 | AW11: =Z11*AA11*(AF11+AN11) -> 2.765e-05 | AX11: =Z11*AA11*(AG11+AO11) -> 0.13035 | AY11: =Z11*AA11*(AH11+AP11) -> 0.0013825 | AZ11: =Z11*AA11*(AI11+AQ11) -> 0.0474
A12: Scenario share check
A13: Scenario | B13: Blend share sum
A14: JetA1_100 | B14: =SUMIF($X$6:$X$20,A14,$Z$6:$Z$20) -> 1
A15: HEFA_40 | B15: =SUMIF($X$6:$X$20,A15,$Z$6:$Z$20) -> 1
A16: HEFA_100 | B16: =SUMIF($X$6:$X$20,A16,$Z$6:$Z$20) -> 1
A17: SynPTL_50 | B17: =SUMIF($X$6:$X$20,A17,$Z$6:$Z$20) -> 1

Sheet Data Quality
A1: Data quality classes
A5: Data_Class | B5: Definition | C5: Default_Uncertainty | D5: Score
A6: Measured | B6: Direct platform-specific measured or official value | C6: 0.05 | D6: 4
A7: Estimated | B7: Engineering estimate grounded in platform-specific evidence | C7: 0.1 | D7: 3
A8: Proxy | B8: Analogous aircraft / subsystem value | C8: 0.2 | D8: 2
A9: Assumed | B9: Rule-of-thumb placeholder or residual closure assumption | C9: 0.3 | D9: 1

Sheet OpenLCA Factors
A1: Example factor lookup table (replace with openLCA export)
A3: Use this sheet to paste or overwrite exported process factors from openLCA / ecoinvent. Keys are referenced throughout the workbook.
A5: Key | B5: Factor_Type | C5: Unit | D5: GWP100 | E5: FDP | F5: PMFP | G5: TAP100 | H5: FEP | I5: HTPinf | J5: IRP_HE | K5: METPinf | L5: Notes
A6: Raw_CFRP | B6: RawMaterial | C6: per kg | D6: 20 | E6: 15 | F6: 0.02 | G6: 0.03 | H6: 0.0012 | I6: 6 | J6: 0.1 | K6: 4 | L6: Example default
A7: Raw_GFRP | B7: RawMaterial | C7: per kg | D7: 5 | E7: 4 | F7: 0.006 | G7: 0.008 | H7: 0.0004 | I7: 1.2 | J7: 0.03 | K7: 0.8 | L7: Example default
A8: Raw_Titanium | B8: RawMaterial | C8: per kg | D8: 35 | E8: 12 | F8: 0.02 | G8: 0.025 | H8: 0.0008 | I8: 8.5 | J8: 0.08 | K8: 5.5 | L8: Example default
A9: Raw_NickelSuperalloy | B9: RawMaterial | C9: per kg | D9: 28 | E9: 10 | F9: 0.018 | G9: 0.02 | H9: 0.0007 | I9: 12 | J9: 0.06 | K9: 6.2 | L9: Example default
A10: Raw_Steel | B10: RawMaterial | C10: per kg | D10: 2.5 | E10: 2 | F10: 0.003 | G10: 0.004 | H10: 0.0002 | I10: 0.9 | J10: 0.02 | K10: 0.5 | L10: Example default
A11: Raw_Aluminium | B11: RawMaterial | C11: per kg | D11: 10 | E11: 7 | F11: 0.01 | G11: 0.012 | H11: 0.0005 | I11: 2.5 | J11: 0.04 | K11: 1.6 | L11: Example default
A12: Raw_Electronics | B12: RawMaterial | C12: per kg | D12: 30 | E12: 18 | F12: 0.025 | G12: 0.018 | H12: 0.0009 | I12: 25 | J12: 0.05 | K12: 10 | L12: Example default
A13: Raw_Other | B13: RawMaterial | C13: per kg | D13: 4 | E13: 3 | F13: 0.004 | G13: 0.005 | H13: 0.0002 | I13: 1 | J13: 0.02 | K13: 0.7 | L13: Example default
A14: Energy_Electricity | B14: ProcessEnergy | C14: per MJ | D14: 0.06 | E14: 0.03 | F14: 6e-05 | G14: 8e-05 | H14: 5e-06 | I14: 0.02 | J14: 0.0005 | K14: 0.01 | L14: Grid electricity intensity
A15: Freight_Road | B15: Transport | C15: per tkm | D15: 0.09 | E15: 0.045 | F15: 0.0001 | G15: 0.00015 | H15: 4e-06 | I15: 0.02 | J15: 0.0001 | K15: 0.006 | L15: Road freight example
A16: Freight_Sea | B16: Transport | C16: per tkm | D16: 0.01 | E16: 0.008 | F16: 2e-05 | G16: 3e-05 | H16: 1e-06 | I16: 0.004 | J16: 5e-05 | K16: 0.002 | L16: Sea freight example
A17: Fuel_WTT_Jet-A1 | B17: FuelWTT | C17: per kg | D17: 0.59 | E17: 0.45 | F17: 0.0012 | G17: 0.002 | H17: 5e-05 | I17: 0.3 | J17: 0.002 | K17: 0.1 | L17: Example Jet-A1 upstream factor
... A46: EOL_Landfill_Other | B46: EOL | C46: per kg | D46: 0.4 | E46: 0.1 | F46: 0.0001 | G46: 0.0002 | H46: 1e-05 | I46: 0.08 | J46: 0 | K46: 0.03 | L46: Illustrative landfill burden

Sheet Calc Materials
A1: Derived material masses and raw-material impacts
A5: Assembly ID | B5: Material | C5: Material Group | D5: Used Mass kg | E5: Normalised Percent | F5: Material Mass kg | G5: Data Class | H5: Uncertainty | I5: Mass x Uncertainty | J5: Override YN | K5: Factor Key | L5: Factor GWP100 | M5: Factor FDP | N5: Factor PMFP | O5: Factor TAP100 | P5: Factor FEP | Q5: Factor HTPinf | R5: Factor IRP HE | S5: Factor METPinf | T5: Impact GWP100 | U5: Impact FDP | V5: Impact PMFP | W5: Impact TAP100 | X5: Impact FEP | Y5: Impact HTPinf | Z5: Impact IRP HE | AA5: Impact METPinf
A6: =Materials!A6 -> FUS | B6: =Materials!B6 -> CFRP | C6: =Materials!C6 -> Composite | D6: =IFERROR(VLOOKUP(A6,Assemblies!$A$6:$N$11,6,FALSE),0) -> 2871 | E6: =Materials!E6 -> 0.81678858 | F6: =D6*E6 -> 2345 | G6: =Materials!F6 -> Estimated | H6: =IFERROR(VLOOKUP(G6,Data [1]Quality!$A$6:$D$9,3,FALSE),0) -> 0 | I6: =F6*H6 -> 0 | J6: =Materials!H6 -> N | K6: ="Raw_"&B6 -> Raw_CFRP | L6: =IFERROR(VLOOKUP($K6,'OpenLCA Factors'!$A$6:$L$200,4,FALSE),0) -> 20 | M6: =IFERROR(VLOOKUP($K6,'OpenLCA Factors'!$A$6:$L$200,5,FALSE),0) -> 15 | N6: =IFERROR(VLOOKUP($K6,'OpenLCA Factors'!$A$6:$L$200,6,FALSE),0) -> 0.02 | O6: =IFERROR(VLOOKUP($K6,'OpenLCA Factors'!$A$6:$L$200,7,FALSE),0) -> 0.03 | P6: =IFERROR(VLOOKUP($K6,'OpenLCA Factors'!$A$6:$L$200,8,FALSE),0) -> 0.0012 | Q6: =IFERROR(VLOOKUP($K6,'OpenLCA Factors'!$A$6:$L$200,9,FALSE),0) -> 6 | R6: =IFERROR(VLOOKUP($K6,'OpenLCA Factors'!$A$6:$L$200,10,FALSE),0) -> 0.1 | S6: =IFERROR(VLOOKUP($K6,'OpenLCA Factors'!$A$6:$L$200,11,FALSE),0) -> 4 | T6: =F6*L6 -> 46900 | U6: =F6*M6 -> 35175 | V6: =F6*N6 -> 46.9 | W6: =F6*O6 -> 70.35 | X6: =F6*P6 -> 2.814 | Y6: =F6*Q6 -> 14070 | Z6: =F6*R6 -> 234.5 | AA6: =F6*S6 -> 9380
A7: =Materials!A7 -> FUS | B7: =Materials!B7 -> GFRP | C7: =Materials!C7 -> Composite | D7: =IFERROR(VLOOKUP(A7,Assemblies!$A$6:$N$11,6,FALSE),0) -> 2871 | E7: =Materials!E7 -> 0.11424591 | F7: =D7*E7 -> 328 | G7: =Materials!F7 -> Estimated | H7: =IFERROR(VLOOKUP(G7,'Data Quality'!$A$6:$D$9,3,FALSE),0) -> 0.1 | I7: =F7*H7 -> 32.8 | J7: =Materials!H7 -> N | K7: ="Raw_"&B7 -> Raw_GFRP | L7: =IFERROR(VLOOKUP($K7,'OpenLCA Factors'!$A$6:$L$200,4,FALSE),0) -> 5 | M7: =IFERROR(VLOOKUP($K7,'OpenLCA Factors'!$A$6:$L$200,5,FALSE),0) -> 4 | N7: =IFERROR(VLOOKUP($K7,'OpenLCA Factors'!$A$6:$L$200,6,FALSE),0) -> 0.006 | O7: =IFERROR(VLOOKUP($K7,'OpenLCA Factors'!$A$6:$L$200,7,FALSE),0) -> 0.008 | P7: =IFERROR(VLOOKUP($K7,'OpenLCA Factors'!$A$6:$L$200,8,FALSE),0) -> 0.0004 | Q7: =IFERROR(VLOOKUP($K7,'OpenLCA Factors'!$A$6:$L$200,9,FALSE),0) -> 1.2 | R7: =IFERROR(VLOOKUP($K7,'OpenLCA Factors'!$A$6:$L$200,10,FALSE),0) -> 0.03 | S7: =IFERROR(VLOOKUP($K7,'OpenLCA Factors'!$A$6:$L$200,11,FALSE),0) -> 0.8 | T7: =F7*L7 -> 1640 | U7: =F7*M7 -> 1312 | V7: =F7*N7 -> 1.968 | W7: =F7*O7 -> 2.624 | X7: =F7*P7 -> 0.1312 | Y7: =F7*Q7 -> 393.6 | Z7: =F7*R7 -> 9.84 | AA7: =F7*S7 -> 262.4
A8: =Materials!A8 -> FUS | B8: =Materials!B8 -> Titanium | C8: =Materials!C8 -> Metal | D8: =IFERROR(VLOOKUP(A8,Assemblies!$A$6:$N$11,6,FALSE),0) -> 2871 | E8: =Materials!E8 -> 0.028039011 | F8: =D8*E8 -> 80.5 | G8: =Materials!F8 -> Estimated | H8: =IFERROR(VLOOKUP(G8,'Data Quality'!$A$6:$D$9,3,FALSE),0) -> 0.1 | I8: =F8*H8 -> 8.05 | J8: =Materials!H8 -> N | K8: ="Raw_"&B8 -> Raw_Titanium | L8: =IFERROR(VLOOKUP($K8,'OpenLCA Factors'!$A$6:$L$200,4,FALSE),0) -> 35 | M8: =IFERROR(VLOOKUP($K8,'OpenLCA Factors'!$A$6:$L$200,5,FALSE),0) -> 12 | N8: =IFERROR(VLOOKUP($K8,'OpenLCA Factors'!$A$6:$L$200,6,FALSE),0) -> 0.02 | O8: =IFERROR(VLOOKUP($K8,'OpenLCA Factors'!$A$6:$L$200,7,FALSE),0) -> 0.025 | P8: =IFERROR(VLOOKUP($K8,'OpenLCA Factors'!$A$6:$L$200,8,FALSE),0) -> 0.0008 | Q8: =IFERROR(VLOOKUP($K8,'OpenLCA Factors'!$A$6:$L$200,9,FALSE),0) -> 8.5 | R8: =IFERROR(VLOOKUP($K8,'OpenLCA Factors'!$A$6:$L$200,10,FALSE),0) -> 0.08 | S8: =IFERROR(VLOOKUP($K8,'OpenLCA Factors'!$A$6:$L$200,11,FALSE),0) -> 5.5 | T8: =F8*L8 -> 2817.5 | U8: =F8*M8 -> 966 | V8: =F8*N8 -> 1.61 | W8: =F8*O8 -> 2.0125 | X8: =F8*P8 -> 0.0644 | Y8: =F8*Q8 -> 684.25 | Z8: =F8*R8 -> 6.44 | AA8: =F8*S8 -> 442.75
A9: =Materials!A9 -> FUS | B9: =Materials!B9 -> NickelSuperalloy | C9: =Materials!C9 -> Metal | D9: =IFERROR(VLOOKUP(A9,Assemblies!$A$6:$N$11,6,FALSE),0) -> 2871 | E9: =Materials!E9 -> 0 | F9: =D9*E9 -> 0 | G9: =Materials!F9 -> Estimated | H9: =IFERROR(VLOOKUP(G9,'Data Quality'!$A$6:$D$9,3,FALSE),0) -> 0.1 | I9: =F9*H9 -> 0 | J9: =Materials!H9 -> N | K9: ="Raw_"&B9 -> Raw_NickelSuperalloy | L9: =IFERROR(VLOOKUP($K9,'OpenLCA Factors'!$A$6:$L$200,4,FALSE),0) -> 28 | M9: =IFERROR(VLOOKUP($K9,'OpenLCA Factors'!$A$6:$L$200,5,FALSE),0) -> 10 | N9: =IFERROR(VLOOKUP($K9,'OpenLCA Factors'!$A$6:$L$200,6,FALSE),0) -> 0.018 | O9: =IFERROR(VLOOKUP($K9,'OpenLCA Factors'!$A$6:$L$200,7,FALSE),0) -> 0.02 | P9: =IFERROR(VLOOKUP($K9,'OpenLCA Factors'!$A$6:$L$200,8,FALSE),0) -> 0.0007 | Q9: =IFERROR(VLOOKUP($K9,'OpenLCA Factors'!$A$6:$L$200,9,FALSE),0) -> 12 | R9: =IFERROR(VLOOKUP($K9,'OpenLCA Factors'!$A$6:$L$200,10,FALSE),0) -> 0.06 | S9: =IFERROR(VLOOKUP($K9,'OpenLCA Factors'!$A$6:$L$200,11,FALSE),0) -> 6.2 | T9: =F9*L9 -> 0 | U9: =F9*M9 -> 0 | V9: =F9*N9 -> 0 | W9: =F9*O9 -> 0 | X9: =F9*P9 -> 0 | Y9: =F9*Q9 -> 0 | Z9: =F9*R9 -> 0 | AA9: =F9*S9 -> 0
A10: =Materials!A10 -> FUS | B10: =Materials!B10 -> Steel | C10: =Materials!C10 -> Metal | D10: =IFERROR(VLOOKUP(A10,Assemblies!$A$6:$N$11,6,FALSE),0) -> 2871 | E10: =Materials!E10 -> 0 | F10: =D10*E10 -> 0 | G10: =Materials!F10 -> Estimated | H10: =IFERROR(VLOOKUP(G10,'Data Quality'!$A$6:$D$9,3,FALSE),0) -> 0.1 | I10: =F10*H10 -> 0 | J10: =Materials!H10 -> N | K10: ="Raw_"&B10 -> Raw_Steel | L10: =IFERROR(VLOOKUP($K10,'OpenLCA Factors'!$A$6:$L$200,4,FALSE),0) -> 2.5 | M10: =IFERROR(VLOOKUP($K10,'OpenLCA Factors'!$A$6:$L$200,5,FALSE),0) -> 2 | N10: =IFERROR(VLOOKUP($K10,'OpenLCA Factors'!$A$6:$L$200,6,FALSE),0) -> 0.003 | O10: =IFERROR(VLOOKUP($K10,'OpenLCA Factors'!$A$6:$L$200,7,FALSE),0) -> 0.004 | P10: =IFERROR(VLOOKUP($K10,'OpenLCA Factors'!$A$6:$L$200,8,FALSE),0) -> 0.0002 | Q10: =IFERROR(VLOOKUP($K10,'OpenLCA Factors'!$A$6:$L$200,9,FALSE),0) -> 0.9 | R10: =IFERROR(VLOOKUP($K10,'OpenLCA Factors'!$A$6:$L$200,10,FALSE),0) -> 0.02 | S10: =IFERROR(VLOOKUP($K10,'OpenLCA Factors'!$A$6:$L$200,11,FALSE),0) -> 0.5 | T10: =F10*L10 -> 0 | U10: =F10*M10 -> 0 | V10: =F10*N10 -> 0 | W10: =F10*O10 -> 0 | X10: =F10*P10 -> 0 | Y10: =F10*Q10 -> 0 | Z10: =F10*R10 -> 0 | AA10: =F10*S10 -> 0
A11: =Materials!A11 -> FUS | B11: =Materials!B11 -> Aluminium | C11: =Materials!C11 -> Metal | D11: =IFERROR(VLOOKUP(A11,Assemblies!$A$6:$N$11,6,FALSE),0) -> 2871 | E11: =Materials!E11 -> 0.028039011 | F11: =D11*E11 -> 80.5 | G11: =Materials!F11 -> Estimated | H11: =IFERROR(VLOOKUP(G11,'Data Quality'!$A$6:$D$9,3,FALSE),0) -> 0.1 | I11: =F11*H11 -> 8.05 | J11: =Materials!H11 -> N | K11: ="Raw_"&B11 -> Raw_Aluminium | L11: =IFERROR(VLOOKUP($K11,'OpenLCA Factors'!$A$6:$L$200,4,FALSE),0) -> 10 | M11: =IFERROR(VLOOKUP($K11,'OpenLCA Factors'!$A$6:$L$200,5,FALSE),0) -> 7 | N11: =IFERROR(VLOOKUP($K11,'OpenLCA Factors'!$A$6:$L$200,6,FALSE),0) -> 0.01 | O11: =IFERROR(VLOOKUP($K11,'OpenLCA Factors'!$A$6:$L$200,7,FALSE),0) -> 0.012 | P11: =IFERROR(VLOOKUP($K11,'OpenLCA Factors'!$A$6:$L$200,8,FALSE),0) -> 0.0005 | Q11: =IFERROR(VLOOKUP($K11,'OpenLCA Factors'!$A$6:$L$200,9,FALSE),0) -> 2.5 | R11: =IFERROR(VLOOKUP($K11,'OpenLCA Factors'!$A$6:$L$200,10,FALSE),0) -> 0.04 | S11: =IFERROR(VLOOKUP($K11,'OpenLCA Factors'!$A$6:$L$200,11,FALSE),0) -> 1.6 | T11: =F11*L11 -> 805 | U11: =F11*M11 -> 563.5 | V11: =F11*N11 -> 0.805 | W11: =F11*O11 -> 0.966 | X11: =F11*P11 -> 0.04025 | Y11: =F11*Q11 -> 201.25 | Z11: =F11*R11 -> 3.22 | AA11: =F11*S11 -> 128.8
A12: =Materials!A12 -> FUS | B12: =Materials!B12 -> Electronics | C12: =Materials!C12 -> Electronics | D12: =IFERROR(VLOOKUP(A12,Assemblies!$A$6:$N$11,6,FALSE),0) -> 2871 | E12: =Materials!E12 -> 0 | F12: =D12*E12 -> 0 | G12: =Materials!F12 -> Estimated | H12: =IFERROR(VLOOKUP(G12,'Data Quality'!$A$6:$D$9,3,FALSE),0) -> 0.1 | I12: =F12*H12 -> 0 | J12: =Materials!H12 -> N | K12: ="Raw_"&B12 -> Raw_Electronics | L12: =IFERROR(VLOOKUP($K12,'OpenLCA Factors'!$A$6:$L$200,4,FALSE),0) -> 30 | M12: =IFERROR(VLOOKUP($K12,'OpenLCA Factors'!$A$6:$L$200,5,FALSE),0) -> 18 | N12: =IFERROR(VLOOKUP($K12,'OpenLCA Factors'!$A$6:$L$200,6,FALSE),0) -> 0.025 | O12: =IFERROR(VLOOKUP($K12,'OpenLCA Factors'!$A$6:$L$200,7,FALSE),0) -> 0.018 | P12: =IFERROR(VLOOKUP($K12,'OpenLCA Factors'!$A$6:$L$200,8,FALSE),0) -> 0.0009 | Q12: =IFERROR(VLOOKUP($K12,'OpenLCA Factors'!$A$6:$L$200,9,FALSE),0) -> 25 | R12: =IFERROR(VLOOKUP($K12,'OpenLCA Factors'!$A$6:$L$200,10,FALSE),0) -> 0.05 | S12: =IFERROR(VLOOKUP($K12,'OpenLCA Factors'!$A$6:$L$200,11,FALSE),0) -> 10 | T12: =F12*L12 -> 0 | U12: =F12*M12 -> 0 | V12: =F12*N12 -> 0 | W12: =F12*O12 -> 0 | X12: =F12*P12 -> 0 | Y12: =F12*Q12 -> 0 | Z12: =F12*R12 -> 0 | AA12: =F12*S12 -> 0
A13: =Materials!A13 -> FUS | B13: =Materials!B13 -> Other | C13: =Materials!C13 -> Other | D13: =IFERROR(VLOOKUP(A13,Assemblies!$A$6:$N$11,6,FALSE),0) -> 2871 | E13: =Materials!E13 -> 0.012887496 | F13: =D13*E13 -> 37 | G13: =Materials!F13 -> Estimated | H13: =IFERROR(VLOOKUP(G13,'Data Quality'!$A$6:$D$9,3,FALSE),0) -> 0.1 | I13: =F13*H13 -> 3.7 | J13: =Materials!H13 -> N | K13: ="Raw_"&B13 -> Raw_Other | L13: =IFERROR(VLOOKUP($K13,'OpenLCA Factors'!$A$6:$L$200,4,FALSE),0) -> 4 | M13: =IFERROR(VLOOKUP($K13,'OpenLCA Factors'!$A$6:$L$200,5,FALSE),0) -> 3 | N13: =IFERROR(VLOOKUP($K13,'OpenLCA Factors'!$A$6:$L$200,6,FALSE),0) -> 0.004 | O13: =IFERROR(VLOOKUP($K13,'OpenLCA Factors'!$A$6:$L$200,7,FALSE),0) -> 0.005 | P13: =IFERROR(VLOOKUP($K13,'OpenLCA Factors'!$A$6:$L$200,8,FALSE),0) -> 0.0002 | Q13: =IFERROR(VLOOKUP($K13,'OpenLCA Factors'!$A$6:$L$200,9,FALSE),0) -> 1 | R13: =IFERROR(VLOOKUP($K13,'OpenLCA Factors'!$A$6:$L$200,10,FALSE),0) -> 0.02 | S13: =IFERROR(VLOOKUP($K13,'OpenLCA Factors'!$A$6:$L$200,11,FALSE),0) -> 0.7 | T13: =F13*L13 -> 148 | U13: =F13*M13 -> 111 | V13: =F13*N13 -> 0.148 | W13: =F13*O13 -> 0.185 | X13: =F13*P13 -> 0.0074 | Y13: =F13*Q13 -> 37 | Z13: =F13*R13 -> 0.74 | AA13: =F13*S13 -> 25.9
A14: =Materials!A14 -> WNG | B14: =Materials!B14 -> CFRP | C14: =Materials!C14 -> Composite | D14: =IFERROR(VLOOKUP(A14,Assemblies!$A$6:$N$11,6,FALSE),0) -> 3970 | E14: =Materials!E14 -> 0.72972292 | F14: =D14*E14 -> 2897 | G14: =Materials!F14 -> Estimated | H14: =IFERROR(VLOOKUP(G14,'Data Quality'!$A$6:$D$9,3,FALSE),0) -> 0.1 | I14: =F14*H14 -> 289.7 | J14: =Materials!H14 -> N | K14: ="Raw_"&B14 -> Raw_CFRP | L14: =IFERROR(VLOOKUP($K14,'OpenLCA Factors'!$A$6:$L$200,4,FALSE),0) -> 20 | M14: =IFERROR(VLOOKUP($K14,'OpenLCA Factors'!$A$6:$L$200,5,FALSE),0) -> 15 | N14: =IFERROR(VLOOKUP($K14,'OpenLCA Factors'!$A$6:$L$200,6,FALSE),0) -> 0.02 | O14: =IFERROR(VLOOKUP($K14,'OpenLCA Factors'!$A$6:$L$200,7,FALSE),0) -> 0.03 | P14: =IFERROR(VLOOKUP($K14,'OpenLCA Factors'!$A$6:$L$200,8,FALSE),0) -> 0.0012 | Q14: =IFERROR(VLOOKUP($K14,'OpenLCA Factors'!$A$6:$L$200,9,FALSE),0) -> 6 | R14: =IFERROR(VLOOKUP($K14,'OpenLCA Factors'!$A$6:$L$200,10,FALSE),0) -> 0.1 | S14: =IFERROR(VLOOKUP($K14,'OpenLCA Factors'!$A$6:$L$200,11,FALSE),0) -> 4 | T14: =F14*L14 -> 57940 | U14: =F14*M14 -> 43455 | V14: =F14*N14 -> 57.94 | W14: =F14*O14 -> 86.91 | X14: =F14*P14 -> 3.4764 | Y14: =F14*Q14 -> 17382 | Z14: =F14*R14 -> 289.7 | AA14: =F14*S14 -> 11588
A15: =Materials!A15 -> WNG | B15: =Materials!B15 -> GFRP | C15: =Materials!C15 -> Composite | D15: =IFERROR(VLOOKUP(A15,Assemblies!$A$6:$N$11,6,FALSE),0) -> 3970 | E15: =Materials!E15 -> 0.11083123 | F15: =D15*E15 -> 440 | G15: =Materials!F15 -> Estimated | H15: =IFERROR(VLOOKUP(G15,'Data Quality'!$A$6:$D$9,3,FALSE),0) -> 0.1 | I15: =F15*H15 -> 44 | J15: =Materials!H15 -> N | K15: ="Raw_"&B15 -> Raw_GFRP | L15: =IFERROR(VLOOKUP($K15,'OpenLCA Factors'!$A$6:$L$200,4,FALSE),0) -> 5 | M15: =IFERROR(VLOOKUP($K15,'OpenLCA Factors'!$A$6:$L$200,5,FALSE),0) -> 4 | N15: =IFERROR(VLOOKUP($K15,'OpenLCA Factors'!$A$6:$L$200,6,FALSE),0) -> 0.006 | O15: =IFERROR(VLOOKUP($K15,'OpenLCA Factors'!$A$6:$L$200,7,FALSE),0) -> 0.008 | P15: =IFERROR(VLOOKUP($K15,'OpenLCA Factors'!$A$6:$L$200,8,FALSE),0) -> 0.0004 | Q15: =IFERROR(VLOOKUP($K15,'OpenLCA Factors'!$A$6:$L$200,9,FALSE),0) -> 1.2 | R15: =IFERROR(VLOOKUP($K15,'OpenLCA Factors'!$A$6:$L$200,10,FALSE),0) -> 0.03 | S15: =IFERROR(VLOOKUP($K15,'OpenLCA Factors'!$A$6:$L$200,11,FALSE),0) -> 0.8 | T15: =F15*L15 -> 2200 | U15: =F15*M15 -> 1760 | V15: =F15*N15 -> 2.64 | W15: =F15*O15 -> 3.52 | X15: =F15*P15 -> 0.176 | Y15: =F15*Q15 -> 528 | Z15: =F15*R15 -> 13.2 | AA15: =F15*S15 -> 352
A16: =Materials!A16 -> WNG | B16: =Materials!B16 -> Titanium | C16: =Materials!C16 -> Metal | D16: =IFERROR(VLOOKUP(A16,Assemblies!$A$6:$N$11,6,FALSE),0) -> 3970 | E16: =Materials!E16 -> 0.12166247 | F16: =D16*E16 -> 483 | G16: =Materials!F16 -> Estimated | H16: =IFERROR(VLOOKUP(G16,'Data Quality'!$A$6:$D$9,3,FALSE),0) -> 0.1 | I16: =F16*H16 -> 48.3 | J16: =Materials!H16 -> N | K16: ="Raw_"&B16 -> Raw_Titanium | L16: =IFERROR(VLOOKUP($K16,'OpenLCA Factors'!$A$6:$L$200,4,FALSE),0) -> 35 | M16: =IFERROR(VLOOKUP($K16,'OpenLCA Factors'!$A$6:$L$200,5,FALSE),0) -> 12 | N16: =IFERROR(VLOOKUP($K16,'OpenLCA Factors'!$A$6:$L$200,6,FALSE),0) -> 0.02 | O16: =IFERROR(VLOOKUP($K16,'OpenLCA Factors'!$A$6:$L$200,7,FALSE),0) -> 0.025 | P16: =IFERROR(VLOOKUP($K16,'OpenLCA Factors'!$A$6:$L$200,8,FALSE),0) -> 0.0008 | Q16: =IFERROR(VLOOKUP($K16,'OpenLCA Factors'!$A$6:$L$200,9,FALSE),0) -> 8.5 | R16: =IFERROR(VLOOKUP($K16,'OpenLCA Factors'!$A$6:$L$200,10,FALSE),0) -> 0.08 | S16: =IFERROR(VLOOKUP($K16,'OpenLCA Factors'!$A$6:$L$200,11,FALSE),0) -> 5.5 | T16: =F16*L16 -> 16905 | U16: =F16*M16 -> 5796 | V16: =F16*N16 -> 9.66 | W16: =F16*O16 -> 12.075 | X16: =F16*P16 -> 0.3864 | Y16: =F16*Q16 -> 4105.5 | Z16: =F16*R16 -> 38.64 | AA16: =F16*S16 -> 2656.5
A17: =Materials!A17 -> WNG | B17: =Materials!B17 -> NickelSuperalloy | C17: =Materials!C17 -> Metal | D17: =IFERROR(VLOOKUP(A17,Assemblies!$A$6:$N$11,6,FALSE),0) -> 3970 | E17: =Materials!E17 -> 0 | F17: =D17*E17 -> 0 | G17: =Materials!F17 -> Estimated | H17: =IFERROR(VLOOKUP(G17,'Data Quality'!$A$6:$D$9,3,FALSE),0) -> 0.1 | I17: =F17*H17 -> 0 | J17: =Materials!H17 -> N | K17: ="Raw_"&B17 -> Raw_NickelSuperalloy | L17: =IFERROR(VLOOKUP($K17,'OpenLCA Factors'!$A$6:$L$200,4,FALSE),0) -> 28 | M17: =IFERROR(VLOOKUP($K17,'OpenLCA Factors'!$A$6:$L$200,5,FALSE),0) -> 10 | N17: =IFERROR(VLOOKUP($K17,'OpenLCA Factors'!$A$6:$L$200,6,FALSE),0) -> 0.018 | O17: =IFERROR(VLOOKUP($K17,'OpenLCA Factors'!$A$6:$L$200,7,FALSE),0) -> 0.02 | P17: =IFERROR(VLOOKUP($K17,'OpenLCA Factors'!$A$6:$L$200,8,FALSE),0) -> 0.0007 | Q17: =IFERROR(VLOOKUP($K17,'OpenLCA Factors'!$A$6:$L$200,9,FALSE),0) -> 12 | R17: =IFERROR(VLOOKUP($K17,'OpenLCA Factors'!$A$6:$L$200,10,FALSE),0) -> 0.06 | S17: =IFERROR(VLOOKUP($K17,'OpenLCA Factors'!$A$6:$L$200,11,FALSE),0) -> 6.2 | T17: =F17*L17 -> 0 | U17: =F17*M17 -> 0 | V17: =F17*N17 -> 0 | W17: =F17*O17 -> 0 | X17: =F17*P17 -> 0 | Y17: =F17*Q17 -> 0 | Z17: =F17*R17 -> 0 | AA17: =F17*S17 -> 0
A18: =Materials!A18 -> WNG | B18: =Materials!B18 -> Steel | C18: =Materials!C18 -> Metal | D18: =IFERROR(VLOOKUP(A18,Assemblies!$A$6:$N$11,6,FALSE),0) -> 3970 | E18: =Materials!E18 -> 0 | F18: =D18*E18 -> 0 | G18: =Materials!F18 -> Estimated | H18: =IFERROR(VLOOKUP(G18,'Data Quality'!$A$6:$D$9,3,FALSE),0) -> 0.1 | I18: =F18*H18 -> 0 | J18: =Materials!H18 -> N | K18: ="Raw_"&B18 -> Raw_Steel | L18: =IFERROR(VLOOKUP($K18,'OpenLCA Factors'!$A$6:$L$200,4,FALSE),0) -> 2.5 | M18: =IFERROR(VLOOKUP($K18,'OpenLCA Factors'!$A$6:$L$200,5,FALSE),0) -> 2 | N18: =IFERROR(VLOOKUP($K18,'OpenLCA Factors'!$A$6:$L$200,6,FALSE),0) -> 0.003 | O18: =IFERROR(VLOOKUP($K18,'OpenLCA Factors'!$A$6:$L$200,7,FALSE),0) -> 0.004 | P18: =IFERROR(VLOOKUP($K18,'OpenLCA Factors'!$A$6:$L$200,8,FALSE),0) -> 0.0002 | Q18: =IFERROR(VLOOKUP($K18,'OpenLCA Factors'!$A$6:$L$200,9,FALSE),0) -> 0.9 | R18: =IFERROR(VLOOKUP($K18,'OpenLCA Factors'!$A$6:$L$200,10,FALSE),0) -> 0.02 | S18: =IFERROR(VLOOKUP($K18,'OpenLCA Factors'!$A$6:$L$200,11,FALSE),0) -> 0.5 | T18: =F18*L18 -> 0 | U18: =F18*M18 -> 0 | V18: =F18*N18 -> 0 | W18: =F18*O18 -> 0 | X18: =F18*P18 -> 0 | Y18: =F18*Q18 -> 0 | Z18: =F18*R18 -> 0 | AA18: =F18*S18 -> 0
... A53: =Materials!A53 -> SYS | B53: =Materials!B53 -> Other | C53: =Materials!C53 -> Other | D53: =IFERROR(VLOOKUP(A53,Assemblies!$A$6:$N$11,6,FALSE),0) -> 257 | E53: =Materials!E53 -> 0.1 | F53: =D53*E53 -> 25.7 | G53: =Materials!F53 -> Assumed | H53: =IFERROR(VLOOKUP(G53,'Data Quality'!$A$6:$D$9,3,FALSE),0) -> 0.3 | I53: =F53*H53 -> 7.71 | J53: =Materials!H53 -> N | K53: ="Raw_"&B53 -> Raw_Other | L53: =IFERROR(VLOOKUP($K53,'OpenLCA Factors'!$A$6:$L$200,4,FALSE),0) -> 4 | M53: =IFERROR(VLOOKUP($K53,'OpenLCA Factors'!$A$6:$L$200,5,FALSE),0) -> 3 | N53: =IFERROR(VLOOKUP($K53,'OpenLCA Factors'!$A$6:$L$200,6,FALSE),0) -> 0.004 | O53: =IFERROR(VLOOKUP($K53,'OpenLCA Factors'!$A$6:$L$200,7,FALSE),0) -> 0.005 | P53: =IFERROR(VLOOKUP($K53,'OpenLCA Factors'!$A$6:$L$200,8,FALSE),0) -> 0.0002 | Q53: =IFERROR(VLOOKUP($K53,'OpenLCA Factors'!$A$6:$L$200,9,FALSE),0) -> 1 | R53: =IFERROR(VLOOKUP($K53,'OpenLCA Factors'!$A$6:$L$200,10,FALSE),0) -> 0.02 | S53: =IFERROR(VLOOKUP($K53,'OpenLCA Factors'!$A$6:$L$200,11,FALSE),0) -> 0.7 | T53: =F53*L53 -> 102.8 | U53: =F53*M53 -> 77.1 | V53: =F53*N53 -> 0.1028 | W53: =F53*O53 -> 0.1285 | X53: =F53*P53 -> 0.00514 | Y53: =F53*Q53 -> 25.7 | Z53: =F53*R53 -> 0.514 | AA53: =F53*S53 -> 17.99
A56: Category totals | T56: GWP100 | U56: FDP | V56: PMFP | W56: TAP100 | X56: FEP | Y56: HTPinf | Z56: IRP_HE | AA56: METPinf
T57: =SUM(T6:T53) -> 225505.7 | U57: =SUM(U6:U53) -> 136592.2 | V57: =SUM(V6:V53) -> 193.2985 | W57: =SUM(W6:W53) -> 271.4418 | X57: =SUM(X6:X53) -> 10.56855 | Y57: =SUM(Y6:Y53) -> 69067.69 | Z57: =SUM(Z6:Z53) -> 899.735 | AA57: =SUM(AA6:AA53) -> 43358.06

Sheet Calc Manufacturing
A1: Manufacturing calculations
A5: Assembly ID | B5: Assembly Name | C5: Used Mass kg | D5: Composite Mass kg | E5: Metal Mass kg | F5: Electronics Mass kg | G5: Other Mass kg | H5: Composite Process Energy MJ | I5: Metal Process Energy MJ | J5: Total Process Energy MJ | K5: Road tkm | L5: Sea tkm | M5: Assembly Uncertainty | N5: Raw GWP100 | O5: Raw FDP | P5: Raw PMFP | Q5: Raw TAP100 | R5: Raw FEP | S5: Raw HTPinf | T5: Raw IRP HE | U5: Raw METPinf | V5: Process GWP100 | W5: Process FDP | X5: Process PMFP | Y5: Process TAP100 | Z5: Process FEP | AA5: Process HTPinf | AB5: Process IRP HE | AC5: Process METPinf | AD5: Transport GWP100 | AE5: Transport FDP | AF5: Transport PMFP | AG5: Transport TAP100 | AH5: Transport FEP | AI5: Transport HTPinf | AJ5: Transport IRP HE | AK5: Transport METPinf | AL5: Manufacturing GWP100 | AM5: Manufacturing FDP | AN5: Manufacturing PMFP | AO5: Manufacturing TAP100 | AP5: Manufacturing FEP | AQ5: Manufacturing HTPinf | AR5: Manufacturing IRP HE | AS5: Manufacturing METPinf | AT5: GWP Low | AU5: GWP Base | AV5: GWP High
A6: =Assemblies!A6 -> FUS | B6: =Assemblies!B6 -> Fuselage | C6: =Assemblies!F6 -> 2871 | D6: =SUMIFS('Calc Materials'!$F$6:$F$53,'Calc Materials'!$A$6:$A$53,$A6,'Calc Materials'!$C$6:$C$53,"Composite") -> 2673 | E6: =SUMIFS('Calc Materials'!$F$6:$F$53,'Calc Materials'!$A$6:$A$53,$A6,'Calc Materials'!$C$6:$C$53,"Metal") -> 161 | F6: =SUMIFS('Calc Materials'!$F$6:$F$53,'Calc Materials'!$A$6:$A$53,$A6,'Calc Materials'!$C$6:$C$53,"Electronics") -> 0 | G6: =SUMIFS('Calc Materials'!$F$6:$F$53,'Calc Materials'!$A$6:$A$53,$A6,'Calc Materials'!$C$6:$C$53,"Other") -> 37 | H6: =D6*104.4 -> 279061.2 | I6: =E6*IF(IFERROR(VLOOKUP($A6,Assemblies!$A$6:$N$11,7,FALSE),"")="Propulsion",28,24) -> 3864 | J6: =H6+I6 -> 282925.2 | K6: =C6/1000*(IFERROR(VLOOKUP($A6,Assemblies!$A$6:$N$11,10,FALSE),0)+IFERROR(VLOOKUP($A6,Assemblies!$A$6:$N$11,12,FALSE),0)) -> 287.1 | L6: =C6/1000*IFERROR(VLOOKUP($A6,Assemblies!$A$6:$N$11,11,FALSE),0) -> 0 | M6: =IF(C6=0,0,SUMIF('Calc Materials'!$A$6:$A$53,$A6,'Calc Materials'!$I$6:$I$53)/C6) -> 0.018321142 | N6: =SUMIF('Calc Materials'!$A$6:$A$53,$A6,'Calc Materials'!$T$6:$T$53) -> 52310.5 | O6: =SUMIF('Calc Materials'!$A$6:$A$53,$A6,'Calc Materials'!$U$6:$U$53) -> 38127.5 | P6: =SUMIF('Calc Materials'!$A$6:$A$53,$A6,'Calc Materials'!$V$6:$V$53) -> 51.431 | Q6: =SUMIF('Calc Materials'!$A$6:$A$53,$A6,'Calc Materials'!$W$6:$W$53) -> 76.1375 | R6: =SUMIF('Calc Materials'!$A$6:$A$53,$A6,'Calc Materials'!$X$6:$X$53) -> 3.05725 | S6: =SUMIF('Calc Materials'!$A$6:$A$53,$A6,'Calc Materials'!$Y$6:$Y$53) -> 15386.1 | T6: =SUMIF('Calc Materials'!$A$6:$A$53,$A6,'Calc Materials'!$Z$6:$Z$53) -> 254.74 | U6: =SUMIF('Calc Materials'!$A$6:$A$53,$A6,'Calc Materials'!$AA$6:$AA$53) -> 10239.85 | V6: =J6*IFERROR(VLOOKUP("Energy Electricity",'OpenLCA Factors'!$A$6:$L$200,4,FALSE),0) -> 0 | W6: =J6*IFERROR(VLOOKUP("Energy Electricity",'OpenLCA Factors'!$A$6:$L$200,5,FALSE),0) -> 0 | X6: =J6*IFERROR(VLOOKUP("Energy Electricity",'OpenLCA Factors'!$A$6:$L$200,6,FALSE),0) -> 0 | Y6: =J6*IFERROR(VLOOKUP("Energy Electricity",'OpenLCA Factors'!$A$6:$L$200,7,FALSE),0) -> 0 | Z6: =J6*IFERROR(VLOOKUP("Energy Electricity",'OpenLCA Factors'!$A$6:$L$200,8,FALSE),0) -> 0 | AA6: =J6*IFERROR(VLOOKUP("Energy Electricity",'OpenLCA Factors'!$A$6:$L$200,9,FALSE),0) -> 0 | AB6: =J6*IFERROR(VLOOKUP("Energy Electricity",'OpenLCA Factors'!$A$6:$L$200,10,FALSE),0) -> 0 | AC6: =J6*IFERROR(VLOOKUP("Energy Electricity",'OpenLCA Factors'!$A$6:$L$200,11,FALSE),0) -> 0 | AD6: =K6*IFERROR(VLOOKUP("Freight Road",'OpenLCA Factors'!$A$6:$L$200,4,FALSE),0)+L6*IFERROR(VLOOKUP("Freight Sea",'OpenLCA Factors'!$A$6:$L$200,4,FALSE),0) -> 0 | AE6: =K6*IFERROR(VLOOKUP("Freight Road",'OpenLCA Factors'!$A$6:$L$200,5,FALSE),0)+L6*IFERROR(VLOOKUP("Freight Sea",'OpenLCA Factors'!$A$6:$L$200,5,FALSE),0) -> 0 | AF6: =K6*IFERROR(VLOOKUP("Freight Road",'OpenLCA Factors'!$A$6:$L$200,6,FALSE),0)+L6*IFERROR(VLOOKUP("Freight Sea",'OpenLCA Factors'!$A$6:$L$200,6,FALSE),0) -> 0 | AG6: =K6*IFERROR(VLOOKUP("Freight Road",'OpenLCA Factors'!$A$6:$L$200,7,FALSE),0)+L6*IFERROR(VLOOKUP("Freight Sea",'OpenLCA Factors'!$A$6:$L$200,7,FALSE),0) -> 0 | AH6: =K6*IFERROR(VLOOKUP("Freight Road",'OpenLCA Factors'!$A$6:$L$200,8,FALSE),0)+L6*IFERROR(VLOOKUP("Freight Sea",'OpenLCA Factors'!$A$6:$L$200,8,FALSE),0) -> 0 | AI6: =K6*IFERROR(VLOOKUP("Freight Road",'OpenLCA Factors'!$A$6:$L$200,9,FALSE),0)+L6*IFERROR(VLOOKUP("Freight Sea",'OpenLCA Factors'!$A$6:$L$200,9,FALSE),0) -> 0 | AJ6: =K6*IFERROR(VLOOKUP("Freight Road",'OpenLCA Factors'!$A$6:$L$200,10,FALSE),0)+L6*IFERROR(VLOOKUP("Freight Sea",'OpenLCA Factors'!$A$6:$L$200,10,FALSE),0) -> 0 | AK6: =K6*IFERROR(VLOOKUP("Freight Road",'OpenLCA Factors'!$A$6:$L$200,11,FALSE),0)+L6*IFERROR(VLOOKUP("Freight Sea",'OpenLCA Factors'!$A$6:$L$200,11,FALSE),0) -> 0 | AL6: =N6+V6+AD6 -> 52310.5 | AM6: =O6+W6+AE6 -> 38127.5 | AN6: =P6+X6+AF6 -> 51.431 | AO6: =Q6+Y6+AG6 -> 76.1375 | AP6: =R6+Z6+AH6 -> 3.05725 | AQ6: =S6+AA6+AI6 -> 15386.1 | AR6: =T6+AB6+AJ6 -> 254.74 | AS6: =U6+AC6+AK6 -> 10239.85 | AT6: =AL6*(1-M6) -> 51352.112 | AU6: =AL6 -> 52310.5 | AV6: =AL6*(1+M6) -> 53268.888
A7: =Assemblies!A7 -> WNG | B7: =Assemblies!B7 -> Wings | C7: =Assemblies!F7 -> 3970 | D7: =SUMIFS('Calc Materials'!$F$6:$F$53,'Calc Materials'!$A$6:$A$53,$A7,'Calc Materials'!$C$6:$C$53,"Composite") -> 3337 | E7: =SUMIFS('Calc Materials'!$F$6:$F$53,'Calc Materials'!$A$6:$A$53,$A7,'Calc Materials'!$C$6:$C$53,"Metal") -> 548 | F7: =SUMIFS('Calc Materials'!$F$6:$F$53,'Calc Materials'!$A$6:$A$53,$A7,'Calc Materials'!$C$6:$C$53,"Electronics") -> 0 | G7: =SUMIFS('Calc Materials'!$F$6:$F$53,'Calc Materials'!$A$6:$A$53,$A7,'Calc Materials'!$C$6:$C$53,"Other") -> 85 | H7: =D7*104.4 -> 348382.8 | I7: =E7*IF(IFERROR(VLOOKUP($A7,Assemblies!$A$6:$N$11,7,FALSE),"")="Propulsion",28,24) -> 13152 | J7: =H7+I7 -> 361534.8 | K7: =C7/1000*(IFERROR(VLOOKUP($A7,Assemblies!$A$6:$N$11,10,FALSE),0)+IFERROR(VLOOKUP($A7,Assemblies!$A$6:$N$11,12,FALSE),0)) -> 992.5 | L7: =C7/1000*IFERROR(VLOOKUP($A7,Assemblies!$A$6:$N$11,11,FALSE),0) -> 3970 | M7: =IF(C7=0,0,SUMIF('Calc Materials'!$A$6:$A$53,$A7,'Calc Materials'!$I$6:$I$53)/C7) -> 0.1 | N7: =SUMIF('Calc Materials'!$A$6:$A$53,$A7,'Calc Materials'!$T$6:$T$53) -> 78035 | O7: =SUMIF('Calc Materials'!$A$6:$A$53,$A7,'Calc Materials'!$U$6:$U$53) -> 51721 | P7: =SUMIF('Calc Materials'!$A$6:$A$53,$A7,'Calc Materials'!$V$6:$V$53) -> 71.23 | Q7: =SUMIF('Calc Materials'!$A$6:$A$53,$A7,'Calc Materials'!$W$6:$W$53) -> 103.71 | R7: =SUMIF('Calc Materials'!$A$6:$A$53,$A7,'Calc Materials'!$X$6:$X$53) -> 4.0883 | S7: =SUMIF('Calc Materials'!$A$6:$A$53,$A7,'Calc Materials'!$Y$6:$Y$53) -> 22263 | T7: =SUMIF('Calc Materials'!$A$6:$A$53,$A7,'Calc Materials'!$Z$6:$Z$53) -> 345.84 | U7: =SUMIF('Calc Materials'!$A$6:$A$53,$A7,'Calc Materials'!$AA$6:$AA$53) -> 14760 | V7: =J7*IFERROR(VLOOKUP("Energy Electricity",'OpenLCA Factors'!$A$6:$L$200,4,FALSE),0) -> 0 | W7: =J7*IFERROR(VLOOKUP("Energy Electricity",'OpenLCA Factors'!$A$6:$L$200,5,FALSE),0) -> 0 | X7: =J7*IFERROR(VLOOKUP("Energy Electricity",'OpenLCA Factors'!$A$6:$L$200,6,FALSE),0) -> 0 | Y7: =J7*IFERROR(VLOOKUP("Energy Electricity",'OpenLCA Factors'!$A$6:$L$200,7,FALSE),0) -> 0 | Z7: =J7*IFERROR(VLOOKUP("Energy Electricity",'OpenLCA Factors'!$A$6:$L$200,8,FALSE),0) -> 0 | AA7: =J7*IFERROR(VLOOKUP("Energy Electricity",'OpenLCA Factors'!$A$6:$L$200,9,FALSE),0) -> 0 | AB7: =J7*IFERROR(VLOOKUP("Energy Electricity",'OpenLCA Factors'!$A$6:$L$200,10,FALSE),0) -> 0 | AC7: =J7*IFERROR(VLOOKUP("Energy Electricity",'OpenLCA Factors'!$A$6:$L$200,11,FALSE),0) -> 0 | AD7: =K7*IFERROR(VLOOKUP("Freight Road",'OpenLCA Factors'!$A$6:$L$200,4,FALSE),0)+L7*IFERROR(VLOOKUP("Freight Sea",'OpenLCA Factors'!$A$6:$L$200,4,FALSE),0) -> 0 | AE7: =K7*IFERROR(VLOOKUP("Freight Road",'OpenLCA Factors'!$A$6:$L$200,5,FALSE),0)+L7*IFERROR(VLOOKUP("Freight Sea",'OpenLCA Factors'!$A$6:$L$200,5,FALSE),0) -> 0 | AF7: =K7*IFERROR(VLOOKUP("Freight Road",'OpenLCA Factors'!$A$6:$L$200,6,FALSE),0)+L7*IFERROR(VLOOKUP("Freight Sea",'OpenLCA Factors'!$A$6:$L$200,6,FALSE),0) -> 0 | AG7: =K7*IFERROR(VLOOKUP("Freight Road",'OpenLCA Factors'!$A$6:$L$200,7,FALSE),0)+L7*IFERROR(VLOOKUP("Freight Sea",'OpenLCA Factors'!$A$6:$L$200,7,FALSE),0) -> 0 | AH7: =K7*IFERROR(VLOOKUP("Freight Road",'OpenLCA Factors'!$A$6:$L$200,8,FALSE),0)+L7*IFERROR(VLOOKUP("Freight Sea",'OpenLCA Factors'!$A$6:$L$200,8,FALSE),0) -> 0 | AI7: =K7*IFERROR(VLOOKUP("Freight Road",'OpenLCA Factors'!$A$6:$L$200,9,FALSE),0)+L7*IFERROR(VLOOKUP("Freight Sea",'OpenLCA Factors'!$A$6:$L$200,9,FALSE),0) -> 0 | AJ7: =K7*IFERROR(VLOOKUP("Freight Road",'OpenLCA Factors'!$A$6:$L$200,10,FALSE),0)+L7*IFERROR(VLOOKUP("Freight Sea",'OpenLCA Factors'!$A$6:$L$200,10,FALSE),0) -> 0 | AK7: =K7*IFERROR(VLOOKUP("Freight Road",'OpenLCA Factors'!$A$6:$L$200,11,FALSE),0)+L7*IFERROR(VLOOKUP("Freight Sea",'OpenLCA Factors'!$A$6:$L$200,11,FALSE),0) -> 0 | AL7: =N7+V7+AD7 -> 78035 | AM7: =O7+W7+AE7 -> 51721 | AN7: =P7+X7+AF7 -> 71.23 | AO7: =Q7+Y7+AG7 -> 103.71 | AP7: =R7+Z7+AH7 -> 4.0883 | AQ7: =S7+AA7+AI7 -> 22263 | AR7: =T7+AB7+AJ7 -> 345.84 | AS7: =U7+AC7+AK7 -> 14760 | AT7: =AL7*(1-M7) -> 70231.5 | AU7: =AL7 -> 78035 | AV7: =AL7*(1+M7) -> 85838.5
